<?xml version="1.0"?>
<robot xmlns:xacro="http://www.ros.org/wiki/xacro">

  <xacro:macro name="hk1d_urdf" params="parent prefix *origin">

    <!-- Color scheme -->
    <xacro:property name="color_base" value="0.8 0.8 0.8 1.0" />
    <xacro:property name="color_link_1" value="0.0 0.0 0.8 1.0" />
    <xacro:property name="color_ee_sphere" value= "1.0 0.2 0.0 1.0"/>

    <xacro:macro name="material" params="name color">
        <material name="${name}">
          <color rgba="${color}"/>
        </material>
    </xacro:macro>

    <xacro:macro name="material_base">
        <xacro:material name="material_base" color="${color_base}" />
    </xacro:macro>

    <xacro:macro name="material_link_1">
        <xacro:material name="material_link_1" color="${color_link_1}" />
    </xacro:macro>

    <xacro:macro name="material_ee">
        <xacro:material name="material_ee" color="${color_ee_sphere}" />
    </xacro:macro>

    <!-- //////////////////// base link //////////////////////-->
    <link name="${prefix}hk1d_base">
        <visual>
            <origin rpy="0 0 0" xyz="0 0 0"/>
            <geometry>
                <cylinder radius="0.0275" length="0.0025"/>
            </geometry>
            <xacro:material_base/>
        </visual>
    </link>

    <joint name="${prefix}hk1d_root_joint" type="fixed">
        <xacro:insert_block name="origin" />
        <parent link="${parent}"/>
        <child link="${prefix}hk1d_base"/>
    </joint>

    <!-- //////////////////// links //////////////////////-->
    <link name="${prefix}link_1">
        <visual>
            <origin rpy="0 0 0" xyz="0.0475 0 0.0"/>
            <geometry>
                <box size="0.095 0.005 0.005"/>
            </geometry>
            <xacro:material_link_1/>
        </visual>
        <inertial>
            <origin xyz="0 0 0" rpy="0 0 0"/>
            <mass value="0.25"/>
            <inertia ixx="0.0"  ixy="0.0"  ixz="0.0" iyy="0.0" iyz="0.0" izz="0.25" />
        </inertial>
      </link>

      <link name="${prefix}ft_sensor" />

      <link name="${prefix}interaction_point">
          <visual>
              <origin rpy="0 0 0" xyz="0 0 0"/>
              <geometry>
                  <sphere radius="0.005"/>
              </geometry>
              <xacro:material_ee/>
          </visual>
      </link>

    <!-- //////////////////// joints //////////////////////-->
      <joint name="${prefix}joint_1" type="revolute">
          <origin rpy="0 0 0" xyz="0 0 0"/>
          <parent link="${prefix}hk1d_base"/>
          <child link="${prefix}link_1"/>
          <axis xyz="0 0 1"/>
          <limit effort="120" velocity="50.0" lower="-20" upper="20" />
      </joint>

      <joint name="${prefix}link_1_to_sensor" type="fixed">
          <origin rpy="0 0 0" xyz="0.07 0 0"/>
          <parent link="${prefix}link_1"/>
          <child link="${prefix}ft_sensor"/>
      </joint>

      <joint name="${prefix}link_1_to_ee" type="fixed">
          <origin rpy="0 0 0" xyz="0.095 0 0"/>
          <parent link="${prefix}link_1"/>
          <child link="${prefix}interaction_point"/>
      </joint>
  </xacro:macro>
</robot>
